Workbook

Sheet Ponte de Comando
A1: N° Doc. | B1: NF | D1: Cliente | E1: NF | F1: Valor (R$)
A2: 19816 | B2: 4935 | C2: 1 | D2: ADERLINDA JOSÉ LIAL -DPU | E2: Venda 4935 29/05/2026 R$2.316,00 | F2: 2316 | G2: =VLOOKUP(A2,'Relatório Vendas por Pedido'!$A$2:$G$252,7,FALSE) -> 2316 | H2: =IF(G2=F2,"OK","ERRO") -> OK
A3: 19579 | B3: 14538 | C3: 2 | D3: AIRTON JOSE BARBOSA DE ANDRADE | E3: Venda 14538 02/05/2026 R$475,00 , CF 14538 | F3: 475 | G3: =VLOOKUP(A3,'Relatório Vendas por Pedido'!$A$2:$G$252,7,FALSE) -> 475 | H3: =IF(G3=F3,"OK","ERRO") -> OK
A4: 19640 | B4: 14536 | C4: 3 | D4: AIRTON JOSE BARBOSA DE ANDRADE | E4: Venda 14536 02/05/2026 R$550,00 , CF 14536 | F4: 550 | G4: =VLOOKUP(A4,'Relatório Vendas por Pedido'!$A$2:$G$252,7,FALSE) -> 520 | H4: =IF(G4=F4,"OK","ERRO") -> ERRO | I4: 30 | J4: outras despesas
A5: 19797 | B5: 14674 | C5: 4 | D5: AIRTON JOSE BARBOSA DE ANDRADE | E5: Venda 14674 21/05/2026 R$520,00 , CF 14674 | F5: 520 | G5: =VLOOKUP(A5,'Relatório Vendas por Pedido'!$A$2:$G$252,7,FALSE) -> 520 | H5: =IF(G5=F5,"OK","ERRO") -> OK
A6: 19866 | B6: 14694 | C6: 5 | D6: AIRTON JOSE BARBOSA DE ANDRADE | E6: Venda 14694 23/05/2026 R$520,00 , CF 14694 | F6: 520 | G6: =VLOOKUP(A6,'Relatório Vendas por Pedido'!$A$2:$G$252,7,FALSE) -> 520 | H6: =IF(G6=F6,"OK","ERRO") -> OK
A7: 19651 | B7: 14543 | C7: 6 | D7: ALAIDE MARTINS DE CERQUEIRA | E7: Venda 14543 04/05/2026 R$16,88 , CF 14543 | F7: 16.88 | G7: =VLOOKUP(A7,'Relatório Vendas por Pedido'!$A$2:$G$252,7,FALSE) -> 16.88 | H7: =IF(G7=F7,"OK","ERRO") -> OK
A8: 19718 | B8: 14588 | C8: 7 | D8: ALAIDE MARTINS DE CERQUEIRA | E8: Venda 14588 11/05/2026 R$452,72 , CF 14588 | F8: 452.72 | G8: =VLOOKUP(A8,'Relatório Vendas por Pedido'!$A$2:$G$252,7,FALSE) -> 452.72 | H8: =IF(G8=F8,"OK","ERRO") -> OK
A9: 19801 | B9: 14653 | C9: 8 | D9: ALAIDE MARTINS DE CERQUEIRA | E9: Venda 14653 18/05/2026 R$81,08 , CF 14653 | F9: 81.08 | G9: =VLOOKUP(A9,'Relatório Vendas por Pedido'!$A$2:$G$252,7,FALSE) -> 81.08 | H9: =IF(G9=F9,"OK","ERRO") -> OK
A10: 19925 | B10: 14727 | C10: 9 | D10: ALAIDE MARTINS DE CERQUEIRA | E10: Venda 14727 29/05/2026 R$435,84 , CF 14727 | F10: 435.84 | G10: =VLOOKUP(A10,'Relatório Vendas por Pedido'!$A$2:$G$252,7,FALSE) -> 435.84 | H10: =IF(G10=F10,"OK","ERRO") -> OK
A11: 19679 | B11: 4918 | C11: 10 | D11: ALICIA NUNES LACERDA - DPU | E11: Venda 4918 25/05/2026 R$2.242,50 | F11: 2242.5 | G11: =VLOOKUP(A11,'Relatório Vendas por Pedido'!$A$2:$G$252,7,FALSE) -> 2242.5 | H11: =IF(G11=F11,"OK","ERRO") -> OK
A12: 19649 | B12: 14553 | C12: 11 | D12: ALTAMIRA LEITE DA SILVA | E12: Venda 14553 04/05/2026 R$166,00 , CF 14553 | F12: 166 | G12: =VLOOKUP(A12,'Relatório Vendas por Pedido'!$A$2:$G$252,7,FALSE) -> 156 | H12: =IF(G12=F12,"OK","ERRO") -> ERRO | I12: 10 | J12: outras despesas
A13: 19705 | B13: 14580 | C13: 12 | D13: ALTAMIRA LEITE DA SILVA | E13: Venda 14580 08/05/2026 R$237,00 , CF 14580 | F13: 237 | G13: =VLOOKUP(A13,'Relatório Vendas por Pedido'!$A$2:$G$252,7,FALSE) -> 227.5 | H13: =IF(G13=F13,"OK","ERRO") -> ERRO | I13: 9.5 | J13: outras despesas
A14: 19749 | B14: 14618 | C14: 13 | D14: ALTAMIRA LEITE DA SILVA | E14: Venda 14618 14/05/2026 R$138,00 , CF 14618 | F14: 138 | G14: =VLOOKUP(A14,'Relatório Vendas por Pedido'!$A$2:$G$252,7,FALSE) -> 128 | H14: =IF(G14=F14,"OK","ERRO") -> ERRO | I14: 10 | J14: outras despesas
A15: 19798 | B15: 14652 | C15: 14 | D15: ALTAMIRA LEITE DA SILVA | E15: Venda 14652 18/05/2026 R$290,00 , CF 14652 | F15: 290 | G15: =VLOOKUP(A15,'Relatório Vendas por Pedido'!$A$2:$G$252,7,FALSE) -> 280 | H15: =IF(G15=F15,"OK","ERRO") -> ERRO | I15: 10 | J15: outras despesas
A16: 19889 | B16: 14713 | C16: 15 | D16: ALTAMIRA LEITE DA SILVA | E16: Venda 14713 27/05/2026 R$290,00 , CF 14713 | F16: 290 | G16: =VLOOKUP(A16,'Relatório Vendas por Pedido'!$A$2:$G$252,7,FALSE) -> 280 | H16: =IF(G16=F16,"OK","ERRO") -> ERRO | I16: 10 | J16: outras despesas
A17: 19757 | B17: 14623 | C17: 16 | D17: ANA BEATRIZ ALVES DA SILVA | E17: Venda 14623 14/05/2026 R$527,00 , CF 14623 | F17: 527 | G17: =VLOOKUP(A17,'Relatório Vendas por Pedido'!$A$2:$G$252,7,FALSE) -> 500 | H17: =IF(G17=F17,"OK","ERRO") -> ERRO | I17: 27 | J17: outras despesas
A18: 19673 | B18: 14560 | C18: 17 | D18: ANALIA MARIA DOS SANTOS | E18: Venda 14560 06/05/2026 R$214,00 , CF 14560 | F18: 214 | G18: =VLOOKUP(A18,'Relatório Vendas por Pedido'!$A$2:$G$252,7,FALSE) -> 200 | H18: =IF(G18=F18,"OK","ERRO") -> ERRO | I18: 14 | J18: outras despesas
A19: 19717 | B19: 14587 | C19: 18 | D19: ANALIA MARIA DOS SANTOS | E19: Venda 14587 11/05/2026 R$554,00 , CF 14587 | F19: 554 | G19: =VLOOKUP(A19,'Relatório Vendas por Pedido'!$A$2:$G$252,7,FALSE) -> 554 | H19: =IF(G19=F19,"OK","ERRO") -> OK
A20: 19882 | B20: 14702 | C20: 19 | D20: ANALIA MARIA DOS SANTOS | E20: Venda 14702 26/05/2026 R$135,00 , CF 14702 | F20: 135 | G20: =VLOOKUP(A20,'Relatório Vendas por Pedido'!$A$2:$G$252,7,FALSE) -> 135 | H20: =IF(G20=F20,"OK","ERRO") -> OK
A21: 19892 | B21: 14708 | C21: 20 | D21: ANALIA MARIA DOS SANTOS | E21: Venda 14708 27/05/2026 R$552,00 , CF 14708 | F21: 552 | G21: =VLOOKUP(A21,'Relatório Vendas por Pedido'!$A$2:$G$252,7,FALSE) -> 552 | H21: =IF(G21=F21,"OK","ERRO") -> OK
A22: 19641 | B22: 14535 | C22: 21 | D22: ANDREY MARTINS DOS SANTOS | E22: Venda 14535 02/05/2026 R$223,00 , CF 14535 | F22: 223 | G22: =VLOOKUP(A22,'Relatório Vendas por Pedido'!$A$2:$G$252,7,FALSE) -> 223 | H22: =IF(G22=F22,"OK","ERRO") -> OK
A23: 19711 | B23: 14584 | C23: 22 | D23: ANDREY MARTINS DOS SANTOS | E23: Venda 14584 11/05/2026 R$517,32 , CF 14584 | F23: 517.32 | G23: =VLOOKUP(A23,'Relatório Vendas por Pedido'!$A$2:$G$252,7,FALSE) -> 517.32 | H23: =IF(G23=F23,"OK","ERRO") -> OK
A24: 19870 | B24: 14698 | C24: 23 | D24: ANDREY MARTINS DOS SANTOS | E24: Venda 14698 25/05/2026 R$331,57 , CF 14698 | F24: 331.57 | G24: =VLOOKUP(A24,'Relatório Vendas por Pedido'!$A$2:$G$252,7,FALSE) -> 317.57 | H24: =IF(G24=F24,"OK","ERRO") -> ERRO | I24: 14 | J24: outras despesas
A25: 19830 | B25: 4907 | C25: 24 | D25: ANDREZA ALVES MONTEIRO COSTA - DROGARIA FARMAIS LTDA | E25: Venda 4907 20/05/2026 R$692,50 | F25: 692.5 | G25: =VLOOKUP(A25,'Relatório Vendas por Pedido'!$A$2:$G$252,7,FALSE) -> 682.5 | H25: =IF(G25=F25,"OK","ERRO") -> ERRO | I25: 10 | J25: outras despesas
A26: 19693 | B26: 14572 | C26: 25 | D26: ANTENOR OLIVEIRA MATOS | E26: Venda 14572 08/05/2026 R$100,00 , CF 14572 | F26: 100 | G26: =VLOOKUP(A26,'Relatório Vendas por Pedido'!$A$2:$G$252,7,FALSE) -> 100 | H26: =IF(G26=F26,"OK","ERRO") -> OK
A27: 19669 | B27: 14557 | C27: 26 | D27: ANTÔNIO JOSÉ DA SILVA ROCHA | E27: Venda 14557 05/05/2026 R$148,00 , CF 14557 | F27: 148 | G27: =VLOOKUP(A27,'Relatório Vendas por Pedido'!$A$2:$G$252,7,FALSE) -> 148 | H27: =IF(G27=F27,"OK","ERRO") -> OK
A28: 19742 | B28: 14612 | C28: 27 | D28: ANTÔNIO JOSÉ DA SILVA ROCHA | E28: Venda 14612 13/05/2026 R$148,00 , CF 14612 | F28: 148 | G28: =VLOOKUP(A28,'Relatório Vendas por Pedido'!$A$2:$G$252,7,FALSE) -> 148 | H28: =IF(G28=F28,"OK","ERRO") -> OK
A29: 19793 | B29: 14649 | C29: 28 | D29: ANTÔNIO JOSÉ DA SILVA ROCHA | E29: Venda 14649 16/05/2026 R$56,00 , CF 14649 | F29: 56 | G29: =VLOOKUP(A29,'Relatório Vendas por Pedido'!$A$2:$G$252,7,FALSE) -> 56 | H29: =IF(G29=F29,"OK","ERRO") -> OK
A30: 19650 | B30: 14552 | C30: 29 | D30: ANTONIO LIMA DE CRISTO | E30: Venda 14552 04/05/2026 R$262,74 , CF 14552 | F30: 262.74 | G30: =VLOOKUP(A30,'Relatório Vendas por Pedido'!$A$2:$G$252,7,FALSE) -> 253.74 | H30: =IF(G30=F30,"OK","ERRO") -> ERRO | I30: 9 | J30: outras despesas
A31: 19575 | B31: 4915 | C31: 30 | D31: ARTUR MIGUEL DE SIQUEIRA BRITO - DPU | E31: Venda 4915 22/05/2026 R$1.771,08 | F31: 1771.08 | G31: =VLOOKUP(A31,'Relatório Vendas por Pedido'!$A$2:$G$252,7,FALSE) -> 1771.08 | H31: =IF(G31=F31,"OK","ERRO") -> OK
A32: 19857 | B32: 4912 | C32: 31 | D32: ASSOCIACAO OBRAS SOCIAIS IRMA DULCE | E32: Venda 4912 22/05/2026 R$2.900,00 | F32: 2900 | G32: =VLOOKUP(A32,'Relatório Vendas por Pedido'!$A$2:$G$252,7,FALSE) -> 2900 | H32: =IF(G32=F32,"OK","ERRO") -> OK
A33: 19653 | B33: 14551 | C33: 32 | D33: Auzira Francisca da Silva Nero | E33: Venda 14551 04/05/2026 R$105,00 , CF 14551 | F33: 105 | G33: =VLOOKUP(A33,'Relatório Vendas por Pedido'!$A$2:$G$252,7,FALSE) -> 90 | H33: =IF(G33=F33,"OK","ERRO") -> ERRO | I33: 15 | J33: outras despesas
A34: 19695 | B34: 14577 | C34: 33 | D34: Auzira Francisca da Silva Nero | E34: Venda 14577 08/05/2026 R$130,00 , CF 14577 | F34: 130 | G34: =VLOOKUP(A34,'Relatório Vendas por Pedido'!$A$2:$G$252,7,FALSE) -> 114 | H34: =IF(G34=F34,"OK","ERRO") -> ERRO | I34: 16 | J34: outras despesas
A35: 19731 | B35: 14605 | C35: 34 | D35: Auzira Francisca da Silva Nero | E35: Venda 14605 12/05/2026 R$125,00 , CF 14605 | F35: 125 | G35: =VLOOKUP(A35,'Relatório Vendas por Pedido'!$A$2:$G$252,7,FALSE) -> 112 | H35: =IF(G35=F35,"OK","ERRO") -> ERRO | I35: 13 | J35: outras despesas
A36: 19776 | B36: 14647 | C36: 35 | D36: Auzira Francisca da Silva Nero | E36: Venda 14647 16/05/2026 R$100,00 , CF 14647 | F36: 100 | G36: =VLOOKUP(A36,'Relatório Vendas por Pedido'!$A$2:$G$252,7,FALSE) -> 88 | H36: =IF(G36=F36,"OK","ERRO") -> ERRO | I36: 12 | J36: outras despesas
A37: 19817 | B37: 14666 | C37: 36 | D37: Auzira Francisca da Silva Nero | E37: Venda 14666 19/05/2026 R$105,00 , CF 14666 | F37: 105 | G37: =VLOOKUP(A37,'Relatório Vendas por Pedido'!$A$2:$G$252,7,FALSE) -> 91 | H37: =IF(G37=F37,"OK","ERRO") -> ERRO | I37: 14 | J37: outras despesas
A38: 19862 | B38: 14690 | C38: 37 | D38: Auzira Francisca da Silva Nero | E38: Venda 14690 23/05/2026 R$100,00 , CF 14690 | F38: 100 | G38: =VLOOKUP(A38,'Relatório Vendas por Pedido'!$A$2:$G$252,7,FALSE) -> 84 | H38: =IF(G38=F38,"OK","ERRO") -> ERRO | I38: 16 | J38: outras despesas
A39: 19902 | B39: 14715 | C39: 38 | D39: Auzira Francisca da Silva Nero | E39: Venda 14715 27/05/2026 R$104,00 , CF 14715 | F39: 104 | G39: =VLOOKUP(A39,'Relatório Vendas por Pedido'!$A$2:$G$252,7,FALSE) -> 90 | H39: =IF(G39=F39,"OK","ERRO") -> ERRO | I39: 14 | J39: outras despesas
A40: 19674 | B40: 14609 | C40: 39 | D40: BARBARA SAYONARA SILVA COSTA | E40: Venda 14609 13/05/2026 R$120,00 , CF 14609 | F40: 120 | G40: =VLOOKUP(A40,'Relatório Vendas por Pedido'!$A$2:$G$252,7,FALSE) -> 120 | H40: =IF(G40=F40,"OK","ERRO") -> OK
...

Sheet Relatório Vendas por Pedido
A1: Nr. Pedido | B1: Valor Bruto | C1: Descontos | D1: Valor Líquido | E1: Valor Líquido com ICMS Subst. | F1: Valor Frete | H1: Pont Com | I1: Status | J1: Diferença
A2: 16620 | B2: 5495.4 | C2: 0 | D2: 5495.4 | E2: 5495.4 | F2: 0 | G2: =E2+F2 -> 5495.4 | H2: 5495.4 | I2: OK
A3: 19329 | B3: 86.82 | C3: 14.82 | D3: 72 | E3: 72 | F3: 0 | G3: =E3+F3 -> 72 | H3: 72 | I3: OK
A4: 19464 | B4: 780 | C4: 0 | D4: 780 | E4: 780 | F4: 0 | G4: =E4+F4 -> 780 | H4: 780 | I4: OK
A5: 19491 | B5: 221.1 | C5: 11.1 | D5: 210 | E5: 210 | F5: 0 | G5: =E5+F5 -> 210 | H5: 210 | I5: OK
A6: 19565 | B6: 2175.38 | C6: 0 | D6: 2175.38 | E6: 2175.38 | F6: 0 | G6: =E6+F6 -> 2175.38 | H6: 2175.38 | I6: OK
A7: 19575 | B7: 1811.76 | C7: 40.68 | D7: 1771.08 | E7: 1771.08 | F7: 0 | G7: =E7+F7 -> 1771.08 | H7: 1771.08 | I7: OK
A8: 19576 | B8: 1670.37 | C8: 0 | D8: 1670.37 | E8: 1670.37 | F8: 0 | G8: =E8+F8 -> 1670.37 | H8: 1670.37 | I8: OK
A9: 19577 | B9: 2017.71 | C9: 0 | D9: 2017.71 | E9: 2017.71 | F9: 0 | G9: =E9+F9 -> 2017.71 | H9: 2017.71 | I9: OK
A10: 19579 | B10: 498.21 | C10: 23.21 | D10: 475 | E10: 475 | F10: 0 | G10: =E10+F10 -> 475 | H10: 475 | I10: OK
A11: 19605 | B11: 500 | C11: 0 | D11: 500 | E11: 500 | F11: 0 | G11: =E11+F11 -> 500 | H11: 500 | I11: OK
A12: 19624 | B12: 2893.6 | C12: 0 | D12: 2893.6 | E12: 2893.6 | F12: 0 | G12: =E12+F12 -> 2893.6 | H12: 2893.6 | I12: OK
A13: 19635 | B13: 1238.27 | C13: 44.7 | D13: 1193.57 | E13: 1193.57 | F13: 30 | G13: =E13+F13 -> 1223.57 | H13: 1223.57 | I13: =IF(G13=H13,"ok","erro") -> ok | J13: =IF(I13="ok","frete","") -> frete
A14: 19637 | B14: 980.82 | C14: 0 | D14: 980.82 | E14: 980.82 | F14: 40.01 | G14: =E14+F14 -> 1020.83 | H14: 1020.82 | I14: ok | J14: frete/arredond
A15: 19640 | B15: 545.32 | C15: 25.32 | D15: 520 | E15: 520 | F15: 0 | G15: =E15+F15 -> 520 | H15: 550 | I15: =IF(G15=H15,"ok","erro") -> erro | J15: outras despesas
A16: 19641 | B16: 233.7 | C16: 10.7 | D16: 223 | E16: 223 | F16: 0 | G16: =E16+F16 -> 223 | H16: 223 | I16: OK
A17: 19642 | B17: 353.64 | C17: 17.64 | D17: 336 | E17: 336 | F17: 0 | G17: =E17+F17 -> 336 | H17: 347 | I17: =IF(G17=H17,"ok","erro") -> erro | J17: outras despesas
A18: 19643 | B18: 176.82 | C18: 8.82 | D18: 168 | E18: 168 | F18: 0 | G18: =E18+F18 -> 168 | H18: 180 | I18: =IF(G18=H18,"ok","erro") -> erro | J18: outras despesas
A19: 19644 | B19: 84.22 | C19: 4.22 | D19: 80 | E19: 80 | F19: 0 | G19: =E19+F19 -> 80 | H19: 80 | I19: OK
A20: 19645 | B20: 354 | C20: 0 | D20: 354 | E20: 354 | F20: 7 | G20: =E20+F20 -> 361 | H20: 361 | I20: =IF(G20=H20,"ok","erro") -> ok | J20: =IF(I20="ok","frete","") -> frete
A21: 19646 | B21: 147.4 | C21: 7.4 | D21: 140 | E21: 140 | F21: 0 | G21: =E21+F21 -> 140 | H21: 140 | I21: OK
A22: 19648 | B22: 2049 | C22: 0 | D22: 2049 | E22: 2049 | F22: 0 | G22: =E22+F22 -> 2049 | H22: 2049 | I22: OK
A23: 19649 | B23: 163.35 | C23: 7.35 | D23: 156 | E23: 156 | F23: 0 | G23: =E23+F23 -> 156 | H23: 166 | I23: =IF(G23=H23,"ok","erro") -> erro | J23: prov. outras desp.
A24: 19650 | B24: 253.74 | C24: 0 | D24: 253.74 | E24: 253.74 | F24: 0 | G24: =E24+F24 -> 253.74 | H24: 262.74 | I24: =IF(G24=H24,"ok","erro") -> erro | J24: prov. outras desp.
A25: 19651 | B25: 16.88 | C25: 0 | D25: 16.88 | E25: 16.88 | F25: 0 | G25: =E25+F25 -> 16.88 | H25: 16.88 | I25: OK
A26: 19652 | B26: 353.64 | C26: 17.64 | D26: 336 | E26: 336 | F26: 0 | G26: =E26+F26 -> 336 | H26: 336 | I26: OK
A27: 19653 | B27: 94.41 | C27: 4.41 | D27: 90 | E27: 90 | F27: 0 | G27: =E27+F27 -> 90 | H27: 105 | I27: =IF(G27=H27,"ok","erro") -> erro | J27: prov. outras desp.
A28: 19654 | B28: 42.11 | C28: 2.11 | D28: 40 | E28: 40 | F28: 0 | G28: =E28+F28 -> 40 | H28: 40 | I28: OK
A29: 19655 | B29: 168.44 | C29: 8.44 | D29: 160 | E29: 160 | F29: 0 | G29: =E29+F29 -> 160 | H29: 160 | I29: OK
A30: 19656 | B30: 139.5 | C30: 0 | D30: 139.5 | E30: 139.5 | F30: 0 | G30: =E30+F30 -> 139.5 | H30: 139.5 | I30: OK
A31: 19657 | B31: 766.92 | C31: 0 | D31: 766.92 | E31: 766.92 | F31: 39.99 | G31: =E31+F31 -> 806.91 | H31: 806.92 | I31: ok | J31: frete/arredond
A32: 19658 | B32: 2114.31 | C32: 0 | D32: 2114.31 | E32: 2114.31 | F32: 0 | G32: =E32+F32 -> 2114.31 | H32: 2114.31 | I32: OK
A33: 19660 | B33: 117.92 | C33: 5.92 | D33: 112 | E33: 112 | F33: 0 | G33: =E33+F33 -> 112 | H33: 112 | I33: OK
A34: 19661 | B34: 40 | C34: 0 | D34: 40 | E34: 40 | F34: 0 | G34: =E34+F34 -> 40 | H34: 40 | I34: OK
A35: 19662 | B35: 117.92 | C35: 5.92 | D35: 112 | E35: 112 | F35: 0 | G35: =E35+F35 -> 112 | H35: 112 | I35: OK
A36: 19663 | B36: 353.64 | C36: 11.64 | D36: 342 | E36: 342 | F36: 0 | G36: =E36+F36 -> 342 | H36: 349 | I36: =IF(G36=H36,"ok","erro") -> erro | J36: prov. outras desp.
A37: 19664 | B37: 120 | C37: 6 | D37: 114 | E37: 114 | F37: 0 | G37: =E37+F37 -> 114 | H37: 114 | I37: OK
A38: 19668 | B38: 383.53 | C38: 12.53 | D38: 371 | E38: 371 | F38: 0 | G38: =E38+F38 -> 371 | H38: 371 | I38: OK
A39: 19669 | B39: 155.35 | C39: 7.35 | D39: 148 | E39: 148 | F39: 0 | G39: =E39+F39 -> 148 | H39: 148 | I39: OK
A40: 19670 | B40: 1214.5 | C40: 239.5 | D40: 975 | E40: 975 | F40: 0 | G40: =E40+F40 -> 975 | H40: 975 | I40: OK
...

Sheet Comissão Vendedores
A1: Vendedor | B1: Pedidos | C1: Total Venda | D1: Comissão
A2: AMANDA SUED TEXEIRA AMORIM | B2: 41 | C2: Vendas sem Nota: R$ 0,00 | D2: Comissão: R$ 0,00
A3: CPF: 100.519.444-05 | C3: Vendas com Nota: R$ 9.945,34 | D3: Devoluções: R$ 0,00
C4: Total Vendas: R$ 9.945,34
C5: Devoluções: R$ 0,00 | D5: Total: R$ 0,00
C7: Total: R$ 9.945,34
A8: GILZETE VIANA MOURA | B8: 17 | C8: Vendas sem Nota: R$ 0,00 | D8: Comissão: R$ 0,00
A9: CPF: 211.847.984-00 | C9: Vendas com Nota: R$ 32.542,49 | D9: Devoluções: R$ 0,00
C10: Total Vendas: R$ 32.542,49
C11: Devoluções: R$ 0,00 | D11: Total: R$ 0,00
C13: Total: R$ 32.542,49
A14: JOSE AMERICO DE SOUSA MOURA JUNIOR | B14: 2 | C14: Vendas sem Nota: R$ 0,00 | D14: Comissão: R$ 0,00
A15: CPF: 113.591.874-05 | C15: Vendas com Nota: R$ 1.707,40 | D15: Devoluções: R$ 0,00
C16: Total Vendas: R$ 1.707,40
C17: Devoluções: R$ 0,00 | D17: Total: R$ 0,00
C19: Total: R$ 1.707,40
A20: LUIS OTAVIO GOMES DO NASCIMENTO CARDOSO MOURA | B20: 17 | C20: Vendas sem Nota: R$ 0,00 | D20: Comissão: R$ 0,00
A21: CPF: 113.592.024-98 | C21: Vendas com Nota: R$ 3.507,31 | D21: Devoluções: R$ 0,00
C22: Total Vendas: R$ 3.507,31
C23: Devoluções: R$ 0,00 | D23: Total: R$ 0,00
C25: Total: R$ 3.507,31
A26: MARIA MIRELI RODRIGUES LEANDRO | B26: 139 | C26: Vendas sem Nota: R$ 0,00 | D26: Comissão: R$ 0,00
A27: CPF: 492.156.408-60 | C27: Vendas com Nota: R$ 40.932,96 | D27: Devoluções: R$ 0,00
C28: Total Vendas: R$ 40.932,96
C29: Devoluções: R$ 1.637,14 | D29: Total: R$ 0,00
C31: Total: R$ 39.295,82
A32: VIRNA GOMES DO NASCIMENTO CARDOSO CHAVES | B32: 35 | C32: Vendas sem Nota: R$ 72,00 | D32: Comissão: R$ 0,00
A33: CPF: 042.954.994-63 | C33: Vendas com Nota: R$ 102.383,17 | D33: Devoluções: R$ 0,00
C34: Total Vendas: R$ 102.455,17
C35: Devoluções: R$ 0,00 | D35: Total: R$ 0,00
C37: Total: R$ 102.455,17
A38: TOTAL VENDAS | B38: 251 | C38: 191090.67 | D38: 0
A39: TOTAL DEVOLUÇÕES | C39: 1637.14 | D39: 0
A40: TOTAL | C40: 189453.53 | D40: 0

Sheet Relatório Vendas por NF
A1: Nr. Nota | B1: Valor Bruto | C1: Descontos | D1: Valor Líquido | E1: Valor Frete | F1: Pont Com | G1: Status
A2: 14535 | B2: 233.7 | C2: 10.7 | D2: 223 | E2: 0 | F2: 223 | G2: OK
A3: 14536 | B3: 575.32 | C3: 25.32 | D3: 550 | E3: 0 | F3: 550 | G3: OK
A4: 14537 | B4: 84.22 | C4: 4.22 | D4: 80 | E4: 0 | F4: 80 | G4: OK
A5: 14538 | B5: 498.21 | C5: 23.21 | D5: 475 | E5: 0 | F5: 475 | G5: OK
A6: 14539 | B6: 188.82 | C6: 8.82 | D6: 180 | E6: 0 | F6: 180 | G6: OK
A7: 14540 | B7: 364.64 | C7: 17.64 | D7: 347 | E7: 0 | F7: 347 | G7: OK
A8: 14541 | B8: 361 | C8: 0 | D8: 361 | E8: 7 | F8: 361 | G8: OK
A9: 14542 | B9: 147.4 | C9: 7.4 | D9: 140 | E9: 0 | F9: 140 | G9: OK
A10: 14543 | B10: 16.88 | C10: 0 | D10: 16.88 | E10: 0 | F10: 16.88 | G10: OK
A11: 14544 | B11: 353.64 | C11: 17.64 | D11: 336 | E11: 0 | F11: 336 | G11: OK
A12: 14545 | B12: 42.11 | C12: 2.11 | D12: 40 | E12: 0 | F12: 40 | G12: OK
A13: 14546 | B13: 168.44 | C13: 8.44 | D13: 160 | E13: 0 | F13: 160 | G13: OK
... A124: 14659 | B124: 111.78 | C124: 4.78 | D124: 107 | E124: 0 | F124: 107 | G124: OK
A125: 14660 | B125: 126.32 | C125: 6.32 | D125: 120 | E125: 0 | F125: 137 | G125: ERRO | H125: pedido 19811 alterado no financeiro
A126: 14661 | B126: 361 | C126: 0 | D126: 361 | E126: 7 | F126: 361 | G126: OK
A127: 14662 | B127: 765.92 | C127: 37.92 | D127: 728 | E127: 0 | F127: 728 | G127: OK
A128: 14663 | B128: 328.4 | C128: 0 | D128: 328.4 | E128: 0 | F128: 328.4 | G128: OK
A129: 14664 | B129: 191.56 | C129: 9.56 | D129: 182 | E129: 0 | F129: 182 | G129: OK
A130: 14665 | B130: 126.32 | C130: 6.32 | D130: 120 | E130: 0 | F130: 120 | G130: OK
A131: 14666 | B131: 108.41 | C131: 3.41 | D131: 105 | E131: 0 | F131: 105 | G131: OK
A132: 14667 | B132: 651.12 | C132: 28.68 | D132: 622.44 | E132: 0 | F132: 622.44 | G132: OK
A133: 14668 | B133: 229.16 | C133: 7.16 | D133: 222 | E133: 0 | F133: 222 | G133: OK
A134: 14669 | B134: 108.7 | C134: 0 | D134: 108.7 | E134: 0 | F134: 108.7 | G134: OK
A135: 14670 | B135: 190.82 | C135: 8.82 | D135: 182 | E135: 0 | F135: 182 | G135: OK
A136: 14671 | B136: 82.1 | C136: 0 | D136: 82.1 | E136: 0 | F136: 82.1 | G136: OK
A137: 14672 | B137: 575.52 | C137: 0 | D137: 575.52 | E137: 0 | F137: 575.52 | G137: OK
... A187: 14722 | B187: 690 | C187: 28.68 | D187: 661.32 | E187: 0 | F187: 661.32 | G187: OK
A188: 14723 | B188: 58.94 | C188: 2.94 | D188: 56 | E188: 0 | F188: 69 | G188: ERRO | H188: pedido 19916 alterado no financeiro
A189: 14724 | B189: 145.28 | C189: 7.28 | D189: 138 | E189: 0 | F189: 138 | G189: OK
A190: 14725 | B190: 52 | C190: 0 | D190: 52 | E190: 0 | F190: 52 | G190: OK
A191: 14726 | B191: 99.99 | C191: 4.99 | D191: 95 | E191: 0 | F191: 95 | G191: OK
A192: 14727 | B192: 435.84 | C192: 0 | D192: 435.84 | E192: 0 | F192: 435.84 | G192: OK
A193: 14728 | B193: 1680 | C193: 42.86 | D193: 1637.14 | E193: 0 | F193: 1637.14 | G193: OK
A194: 14729 | B194: 287.34 | C194: 14.34 | D194: 273 | E194: 0 | F194: 273 | G194: OK
A195: 14730 | B195: 581.68 | C195: 28.68 | D195: 553 | E195: 0 | F195: 553 | G195: OK
A196: 14731 | B196: 220.55 | C196: 10.55 | D196: 210 | E196: 0 | F196: 210 | G196: OK
A197: 14732 | B197: 221.1 | C197: 11.1 | D197: 210 | E197: 0 | F197: 210 | G197: OK
A198: 14733 | B198: 361 | C198: 0 | D198: 361 | E198: 7 | F198: 361 | G198: OK
A199: 14734 | B199: 435.84 | C199: 0 | D199: 435.84 | E199: 0 | F199: 435.84 | G199: OK
...
